Workbook

Sheet pokemon
A1: pokedex_number | B1: pokedex_name | C1: type_1 | D1: type_2 | E1: hp | F1: atk | G1: def | H1: sp_atk | I1: sp_def | J1: spd | K1: classification | L1: biome | M1: climate | N1: _initiative | O1: _health | P1: i_mod | Q1: h_mod | R1: initiative | S1: health | T1: total | U1: move_1 | V1: move_2 | W1: move_3 | X1: move_4 | Y1: evolve_into | Z1: evolve_cost | AA1: internal_name | AB1: description | AC1: move_name | AD1: move_type | AE1: move_attack_strength | AF1: move_effect | AG1: is_starter | AH1: is_legendary | AI1: is_shiny | AJ1: encounter_tier | AK1: trainer | AL1: evo_only | AM1: number_in_deck | AN1: uncapturable | AO1: state
A2: 1 | B2: Bulbasaur | C2: Grass | D2: Poison | E2: 45 | F2: 49 | G2: 49 | H2: 65 | I2: 65 | J2: 45 | K2: Seed Pokémon | L2: Forest | M2: Temperate | N2: 5.54 | O2: 5.22 | P2: -1 | R2: =MROUND(N2,1)+P2 -> 5 | S2: =MROUND(O2,1)+Q2 -> 5 | T2: =SUM(S2,R2) -> 10 | U2: Grass | V2: Poison | W2: Dark | X2: Ground | Y2: Ivysaur | Z2: {=IF(ISBLANK(AK2),_xlfn.LET( _xlpm.nameBeforeSlash, IF(ISNUMBER(SEARCH("/", Y2)), LEFT(Y2, SEARCH("/", Y2)-1), Y2), _xlpm.matchRow, IFERROR(MATCH(_xlpm.nameBeforeSlash, AA:AA, 0), ""), _xlpm.difference, IF(_xlpm.matchRow="", "", ABS((R2 + S2) - (INDEX(R:R, _xlpm.matchRow) + INDEX(S:S, _xlpm.matchRow)))), _xlpm.category, IF(_xlpm.matchRow="", "", INDEX(AJ:AJ, _xlpm.matchRow)), _xlpm.adjustment, IF(_xlpm.matchRow="", "", IF(_xlpm.category="weak", 2, IF(_xlpm.category="moderate", 4, IF(_xlpm.category="strong", 8, IF(_xlpm.category="legendary", _xlpm.difference + 12, IF(_xlpm.category="warp", _xlpm.difference + 12, 0)))))), _xlpm.result, IF(_xlpm.matchRow="", "", IF(_xlpm.category="legendary", _xlpm.adjustment, _xlpm.difference + _xlpm.adjustment)), _xlpm.result ),IF(ISBLANK(Y2),"","Hidden"))} -> 8 | AA2: Bulbasaur | AC2: Vine Whip | AD2: =_xlfn.XLOOKUP(AC2,moves!A:A,moves!B:B) -> grass | AE2: =_xlfn.XLOOKUP(AC2,moves!A:A,moves!D:D) -> 2 | AF2: =_xlfn.XLOOKUP(AC2,moves!A:A,moves!E:E) -> Status symbols deal +1 damage. | AG2: 1 | AH2: 0 | AI2: =IF(ISNUMBER(SEARCH("Shiny ", AA2)), 1, 0) -> 0 | AJ2: starter | AL2: 0 | AM2: {=IF(AL2=1,1, IF(ISTEXT(AK2),1, IF(AO2>1,AM1, IF(AI2=1, IF(SUMPRODUCT((LEN($Y$2:$Y$4096)-LEN(SUBSTITUTE($Y$2:$Y$4096,AA2,"")))/LEN(AA2))>0,2,1), IF( SUMPRODUCT((LEN($Y$2:$Y$4096)-LEN(SUBSTITUTE($Y$2:$Y$4096,AA2,"")))/LEN(AA2)) - SUMPRODUCT((LEN($Y$2:$Y$4096)-LEN(SUBSTITUTE($Y$2:$Y$4096,"Alolan "&AA2,"")))/LEN("Alolan "&AA2)) - SUMPRODUCT((LEN($Y$2:$Y$4096)-LEN(SUBSTITUTE($Y$2:$Y$4096,"Galarian "&AA2,"")))/LEN("Galarian "&AA2)) - SUMPRODUCT((LEN($Y$2:$Y$4096)-LEN(SUBSTITUTE($Y$2:$Y$4096,"Hisuian "&AA2,"")))/LEN("Hisuian "&AA2)) - SUMPRODUCT((LEN($Y$2:$Y$4096)-LEN(SUBSTITUTE($Y$2:$Y$4096,"Paldean "&AA2,"")))/LEN("Paldean "&AA2)) >0,2,1) ))))} -> 1 | AN2: 0 | AO2: 0
A3: 1 | B3: Bulbasaur | C3: Grass | D3: Poison | E3: 45 | F3: 49 | G3: 49 | H3: 65 | I3: 65 | J3: 45 | K3: Seed Pokémon | L3: Forest | M3: Temperate | N3: 5.54 | O3: 5.22 | P3: -1 | R3: =MROUND(N3,1)+P3 -> 5 | S3: =MROUND(O3,1)+Q3 -> 5 | T3: =SUM(S3,R3) -> 10 | U3: Grass | V3: Poison | W3: Dark | X3: Ground | Y3: Ivysaur | Z3: {=IF(ISBLANK(AK3),_xlfn.LET( _xlpm.nameBeforeSlash, IF(ISNUMBER(SEARCH("/", Y3)), LEFT(Y3, SEARCH("/", Y3)-1), Y3), _xlpm.matchRow, IFERROR(MATCH(_xlpm.nameBeforeSlash, AA:AA, 0), ""), _xlpm.difference, IF(_xlpm.matchRow="", "", ABS((R3 + S3) - (INDEX(R:R, _xlpm.matchRow) + INDEX(S:S, _xlpm.matchRow)))), _xlpm.category, IF(_xlpm.matchRow="", "", INDEX(AJ:AJ, _xlpm.matchRow)), _xlpm.adjustment, IF(_xlpm.matchRow="", "", IF(_xlpm.category="weak", 2, IF(_xlpm.category="moderate", 4, IF(_xlpm.category="strong", 8, IF(_xlpm.category="legendary", _xlpm.difference + 12, IF(_xlpm.category="warp", _xlpm.difference + 12, 0)))))), _xlpm.result, IF(_xlpm.matchRow="", "", IF(_xlpm.category="legendary", _xlpm.adjustment, _xlpm.difference + _xlpm.adjustment)), _xlpm.result ),IF(ISBLANK(Y3),"","Hidden"))} -> 8 | AA3: Bulbasaur | AC3: Vine Whip | AD3: =_xlfn.XLOOKUP(AC3,moves!A:A,moves!B:B) -> grass | AE3: =_xlfn.XLOOKUP(AC3,moves!A:A,moves!D:D) -> 2 | AF3: =_xlfn.XLOOKUP(AC3,moves!A:A,moves!E:E) -> Status symbols deal +1 damage. | AG3: 0 | AH3: 0 | AI3: =IF(ISNUMBER(SEARCH("Shiny ", AA3)), 1, 0) -> 0 | AJ3: weak | AL3: 0 | AM3: {=IF(AL3=1,1, IF(ISTEXT(AK3),1, IF(AO3>1,AM2, IF(AI3=1, IF(SUMPRODUCT((LEN($Y$2:$Y$4096)-LEN(SUBSTITUTE($Y$2:$Y$4096,AA3,"")))/LEN(AA3))>0,2,1), IF( SUMPRODUCT((LEN($Y$2:$Y$4096)-LEN(SUBSTITUTE($Y$2:$Y$4096,AA3,"")))/LEN(AA3)) - SUMPRODUCT((LEN($Y$2:$Y$4096)-LEN(SUBSTITUTE($Y$2:$Y$4096,"Alolan "&AA3,"")))/LEN("Alolan "&AA3)) - SUMPRODUCT((LEN($Y$2:$Y$4096)-LEN(SUBSTITUTE($Y$2:$Y$4096,"Galarian "&AA3,"")))/LEN("Galarian "&AA3)) - SUMPRODUCT((LEN($Y$2:$Y$4096)-LEN(SUBSTITUTE($Y$2:$Y$4096,"Hisuian "&AA3,"")))/LEN("Hisuian "&AA3)) - SUMPRODUCT((LEN($Y$2:$Y$4096)-LEN(SUBSTITUTE($Y$2:$Y$4096,"Paldean "&AA3,"")))/LEN("Paldean "&AA3)) >0,2,1) ))))} -> 1 | AN3: 0 | AO3: 0
A4: 1 | B4: Bulbasaur | C4: Grass | D4: Poison | E4: 45 | F4: 49 | G4: 49 | H4: 65 | I4: 65 | J4: 45 | K4: Seed Pokémon | L4: Forest | M4: Temperate | N4: 5.54 | O4: 5.22 | P4: -1 | R4: =MROUND(N4,1)+P4 -> 5 | S4: =MROUND(O4,1)+Q4 -> 5 | T4: =SUM(S4,R4) -> 10 | U4: Grass | V4: Poison | W4: Dark | X4: Ground | Y4: Ivysaur | Z4: {=IF(ISBLANK(AK4),_xlfn.LET( _xlpm.nameBeforeSlash, IF(ISNUMBER(SEARCH("/", Y4)), LEFT(Y4, SEARCH("/", Y4)-1), Y4), _xlpm.matchRow, IFERROR(MATCH(_xlpm.nameBeforeSlash, AA:AA, 0), ""), _xlpm.difference, IF(_xlpm.matchRow="", "", ABS((R4 + S4) - (INDEX(R:R, _xlpm.matchRow) + INDEX(S:S, _xlpm.matchRow)))), _xlpm.category, IF(_xlpm.matchRow="", "", INDEX(AJ:AJ, _xlpm.matchRow)), _xlpm.adjustment, IF(_xlpm.matchRow="", "", IF(_xlpm.category="weak", 2, IF(_xlpm.category="moderate", 4, IF(_xlpm.category="strong", 8, IF(_xlpm.category="legendary", _xlpm.difference + 12, IF(_xlpm.category="warp", _xlpm.difference + 12, 0)))))), _xlpm.result, IF(_xlpm.matchRow="", "", IF(_xlpm.category="legendary", _xlpm.adjustment, _xlpm.difference + _xlpm.adjustment)), _xlpm.result ),IF(ISBLANK(Y4),"","Hidden"))} -> 8 | AA4: Bulbasaur | AC4: Vine Whip | AD4: =_xlfn.XLOOKUP(AC4,moves!A:A,moves!B:B) -> grass | AE4: =_xlfn.XLOOKUP(AC4,moves!A:A,moves!D:D) -> 2 | AF4: =_xlfn.XLOOKUP(AC4,moves!A:A,moves!E:E) -> Status symbols deal +1 damage. | AG4: 0 | AH4: 0 | AI4: =IF(ISNUMBER(SEARCH("Shiny ", AA4)), 1, 0) -> 0 | AJ4: weak | AL4: 0 | AM4: {=IF(AL4=1,1, IF(ISTEXT(AK4),1, IF(AO4>1,AM3, IF(AI4=1, IF(SUMPRODUCT((LEN($Y$2:$Y$4096)-LEN(SUBSTITUTE($Y$2:$Y$4096,AA4,"")))/LEN(AA4))>0,2,1), IF( SUMPRODUCT((LEN($Y$2:$Y$4096)-LEN(SUBSTITUTE($Y$2:$Y$4096,AA4,"")))/LEN(AA4)) - SUMPRODUCT((LEN($Y$2:$Y$4096)-LEN(SUBSTITUTE($Y$2:$Y$4096,"Alolan "&AA4,"")))/LEN("Alolan "&AA4)) - SUMPRODUCT((LEN($Y$2:$Y$4096)-LEN(SUBSTITUTE($Y$2:$Y$4096,"Galarian "&AA4,"")))/LEN("Galarian "&AA4)) - SUMPRODUCT((LEN($Y$2:$Y$4096)-LEN(SUBSTITUTE($Y$2:$Y$4096,"Hisuian "&AA4,"")))/LEN("Hisuian "&AA4)) - SUMPRODUCT((LEN($Y$2:$Y$4096)-LEN(SUBSTITUTE($Y$2:$Y$4096,"Paldean "&AA4,"")))/LEN("Paldean "&AA4)) >0,2,1) ))))} -> 1 | AN4: 0 | AO4: 0
A5: 1 | B5: Bulbasaur | C5: Grass | D5: Poison | E5: 45 | F5: 49 | G5: 49 | H5: 65 | I5: 65 | J5: 45 | K5: Seed Pokémon | L5: Forest | M5: Temperate | N5: 5.54 | O5: 5.22 | P5: -1 | R5: =MROUND(N5,1)+P5 -> 5 | S5: =MROUND(O5,1)+Q5 -> 5 | T5: =SUM(S5,R5) -> 10 | U5: Grass | V5: Poison | W5: Dark | X5: Ground | Y5: Ivysaur | Z5: {=IF(ISBLANK(AK5),_xlfn.LET( _xlpm.nameBeforeSlash, IF(ISNUMBER(SEARCH("/", Y5)), LEFT(Y5, SEARCH("/", Y5)-1), Y5), _xlpm.matchRow, IFERROR(MATCH(_xlpm.nameBeforeSlash, AA:AA, 0), ""), _xlpm.difference, IF(_xlpm.matchRow="", "", ABS((R5 + S5) - (INDEX(R:R, _xlpm.matchRow) + INDEX(S:S, _xlpm.matchRow)))), _xlpm.category, IF(_xlpm.matchRow="", "", INDEX(AJ:AJ, _xlpm.matchRow)), _xlpm.adjustment, IF(_xlpm.matchRow="", "", IF(_xlpm.category="weak", 2, IF(_xlpm.category="moderate", 4, IF(_xlpm.category="strong", 8, IF(_xlpm.category="legendary", _xlpm.difference + 12, IF(_xlpm.category="warp", _xlpm.difference + 12, 0)))))), _xlpm.result, IF(_xlpm.matchRow="", "", IF(_xlpm.category="legendary", _xlpm.adjustment, _xlpm.difference + _xlpm.adjustment)), _xlpm.result ),IF(ISBLANK(Y5),"","Hidden"))} -> 8 | AA5: Bulbasaur | AC5: Vine Whip | AD5: =_xlfn.XLOOKUP(AC5,moves!A:A,moves!B:B) -> grass | AE5: =_xlfn.XLOOKUP(AC5,moves!A:A,moves!D:D) -> 2 | AF5: =_xlfn.XLOOKUP(AC5,moves!A:A,moves!E:E) -> Status symbols deal +1 damage. | AG5: 0 | AH5: 0 | AI5: =IF(ISNUMBER(SEARCH("Shiny ", AA5)), 1, 0) -> 0 | AJ5: weak | AL5: 0 | AM5: {=IF(AL5=1,1, IF(ISTEXT(AK5),1, IF(AO5>1,AM4, IF(AI5=1, IF(SUMPRODUCT((LEN($Y$2:$Y$4096)-LEN(SUBSTITUTE($Y$2:$Y$4096,AA5,"")))/LEN(AA5))>0,2,1), IF( SUMPRODUCT((LEN($Y$2:$Y$4096)-LEN(SUBSTITUTE($Y$2:$Y$4096,AA5,"")))/LEN(AA5)) - SUMPRODUCT((LEN($Y$2:$Y$4096)-LEN(SUBSTITUTE($Y$2:$Y$4096,"Alolan "&AA5,"")))/LEN("Alolan "&AA5)) - SUMPRODUCT((LEN($Y$2:$Y$4096)-LEN(SUBSTITUTE($Y$2:$Y$4096,"Galarian "&AA5,"")))/LEN("Galarian "&AA5)) - SUMPRODUCT((LEN($Y$2:$Y$4096)-LEN(SUBSTITUTE($Y$2:$Y$4096,"Hisuian "&AA5,"")))/LEN("Hisuian "&AA5)) - SUMPRODUCT((LEN($Y$2:$Y$4096)-LEN(SUBSTITUTE($Y$2:$Y$4096,"Paldean "&AA5,"")))/LEN("Paldean "&AA5)) >0,2,1) ))))} -> 1 | AN5: 0 | AO5: 0
A6: 1 | B6: Bulbasaur | C6: Grass | D6: Poison | E6: 45 | F6: 49 | G6: 49 | H6: 65 | I6: 65 | J6: 45 | K6: Seed Pokémon | L6: Forest | M6: Temperate | N6: 5.54 | O6: 5.22 | P6: -1 | R6: =MROUND(N6,1)+P6 -> 5 | S6: =MROUND(O6,1)+Q6 -> 5 | T6: =SUM(S6,R6) -> 10 | U6: Grass | V6: Poison | W6: Dark | X6: Ground | Y6: Ivysaur | Z6: {=IF(ISBLANK(AK6),_xlfn.LET( _xlpm.nameBeforeSlash, IF(ISNUMBER(SEARCH("/", Y6)), LEFT(Y6, SEARCH("/", Y6)-1), Y6), _xlpm.matchRow, IFERROR(MATCH(_xlpm.nameBeforeSlash, AA:AA, 0), ""), _xlpm.difference, IF(_xlpm.matchRow="", "", ABS((R6 + S6) - (INDEX(R:R, _xlpm.matchRow) + INDEX(S:S, _xlpm.matchRow)))), _xlpm.category, IF(_xlpm.matchRow="", "", INDEX(AJ:AJ, _xlpm.matchRow)), _xlpm.adjustment, IF(_xlpm.matchRow="", "", IF(_xlpm.category="weak", 2, IF(_xlpm.category="moderate", 4, IF(_xlpm.category="strong", 8, IF(_xlpm.category="legendary", _xlpm.difference + 12, IF(_xlpm.category="warp", _xlpm.difference + 12, 0)))))), _xlpm.result, IF(_xlpm.matchRow="", "", IF(_xlpm.category="legendary", _xlpm.adjustment, _xlpm.difference + _xlpm.adjustment)), _xlpm.result ),IF(ISBLANK(Y6),"","Hidden"))} -> 8 | AA6: Bulbasaur | AC6: Vine Whip | AD6: =_xlfn.XLOOKUP(AC6,moves!A:A,moves!B:B) -> grass | AE6: =_xlfn.XLOOKUP(AC6,moves!A:A,moves!D:D) -> 2 | AF6: =_xlfn.XLOOKUP(AC6,moves!A:A,moves!E:E) -> Status symbols deal +1 damage. | AG6: 0 | AH6: 0 | AI6: =IF(ISNUMBER(SEARCH("Shiny ", AA6)), 1, 0) -> 0 | AJ6: weak | AL6: 0 | AM6: {=IF(AL6=1,1, IF(ISTEXT(AK6),1, IF(AO6>1,AM5, IF(AI6=1, IF(SUMPRODUCT((LEN($Y$2:$Y$4096)-LEN(SUBSTITUTE($Y$2:$Y$4096,AA6,"")))/LEN(AA6))>0,2,1), IF( SUMPRODUCT((LEN($Y$2:$Y$4096)-LEN(SUBSTITUTE($Y$2:$Y$4096,AA6,"")))/LEN(AA6)) - SUMPRODUCT((LEN($Y$2:$Y$4096)-LEN(SUBSTITUTE($Y$2:$Y$4096,"Alolan "&AA6,"")))/LEN("Alolan "&AA6)) - SUMPRODUCT((LEN($Y$2:$Y$4096)-LEN(SUBSTITUTE($Y$2:$Y$4096,"Galarian "&AA6,"")))/LEN("Galarian "&AA6)) - SUMPRODUCT((LEN($Y$2:$Y$4096)-LEN(SUBSTITUTE($Y$2:$Y$4096,"Hisuian "&AA6,"")))/LEN("Hisuian "&AA6)) - SUMPRODUCT((LEN($Y$2:$Y$4096)-LEN(SUBSTITUTE($Y$2:$Y$4096,"Paldean "&AA6,"")))/LEN("Paldean "&AA6)) >0,2,1) ))))} -> 1 | AN6: 0 | AO6: 0
A7: 1 | B7: Bulbasaur | C7: Grass | D7: Poison | E7: 45 | F7: 49 | G7: 49 | H7: 65 | I7: 65 | J7: 45 | K7: Seed Pokémon | L7: Forest | M7: Temperate | N7: 5.54 | O7: 5.22 | P7: -1 | R7: =MROUND(N7,1)+P7 -> 5 | S7: =MROUND(O7,1)+Q7 -> 5 | T7: =SUM(S7,R7) -> 10 | U7: Grass | V7: Poison | W7: Dark | X7: Ground | Y7: Ivysaur | Z7: {=IF(ISBLANK(AK7),_xlfn.LET( _xlpm.nameBeforeSlash, IF(ISNUMBER(SEARCH("/", Y7)), LEFT(Y7, SEARCH("/", Y7)-1), Y7), _xlpm.matchRow, IFERROR(MATCH(_xlpm.nameBeforeSlash, AA:AA, 0), ""), _xlpm.difference, IF(_xlpm.matchRow="", "", ABS((R7 + S7) - (INDEX(R:R, _xlpm.matchRow) + INDEX(S:S, _xlpm.matchRow)))), _xlpm.category, IF(_xlpm.matchRow="", "", INDEX(AJ:AJ, _xlpm.matchRow)), _xlpm.adjustment, IF(_xlpm.matchRow="", "", IF(_xlpm.category="weak", 2, IF(_xlpm.category="moderate", 4, IF(_xlpm.category="strong", 8, IF(_xlpm.category="legendary", _xlpm.difference + 12, IF(_xlpm.category="warp", _xlpm.difference + 12, 0)))))), _xlpm.result, IF(_xlpm.matchRow="", "", IF(_xlpm.category="legendary", _xlpm.adjustment, _xlpm.difference + _xlpm.adjustment)), _xlpm.result ),IF(ISBLANK(Y7),"","Hidden"))} -> 8 | AA7: Bulbasaur | AC7: Vine Whip | AD7: =_xlfn.XLOOKUP(AC7,moves!A:A,moves!B:B) -> grass | AE7: =_xlfn.XLOOKUP(AC7,moves!A:A,moves!D:D) -> 2 | AF7: =_xlfn.XLOOKUP(AC7,moves!A:A,moves!E:E) -> Status symbols deal +1 damage. | AG7: 0 | AH7: 0 | AI7: =IF(ISNUMBER(SEARCH("Shiny ", AA7)), 1, 0) -> 0 | AJ7: weak | AL7: 0 | AM7: {=IF(AL7=1,1, IF(ISTEXT(AK7),1, IF(AO7>1,AM6, IF(AI7=1, IF(SUMPRODUCT((LEN($Y$2:$Y$4096)-LEN(SUBSTITUTE($Y$2:$Y$4096,AA7,"")))/LEN(AA7))>0,2,1), IF( SUMPRODUCT((LEN($Y$2:$Y$4096)-LEN(SUBSTITUTE($Y$2:$Y$4096,AA7,"")))/LEN(AA7)) - SUMPRODUCT((LEN($Y$2:$Y$4096)-LEN(SUBSTITUTE($Y$2:$Y$4096,"Alolan "&AA7,"")))/LEN("Alolan "&AA7)) - SUMPRODUCT((LEN($Y$2:$Y$4096)-LEN(SUBSTITUTE($Y$2:$Y$4096,"Galarian "&AA7,"")))/LEN("Galarian "&AA7)) - SUMPRODUCT((LEN($Y$2:$Y$4096)-LEN(SUBSTITUTE($Y$2:$Y$4096,"Hisuian "&AA7,"")))/LEN("Hisuian "&AA7)) - SUMPRODUCT((LEN($Y$2:$Y$4096)-LEN(SUBSTITUTE($Y$2:$Y$4096,"Paldean "&AA7,"")))/LEN("Paldean "&AA7)) >0,2,1) ))))} -> 1 | AN7: 0 | AO7: 0
A8: 1 | B8: Bulbasaur | C8: Grass | D8: Poison | E8: 45 | F8: 49 | G8: 49 | H8: 65 | I8: 65 | J8: 45 | K8: Seed Pokémon | L8: Forest | M8: Temperate | N8: 5.54 | O8: 5.22 | P8: -1 | R8: =MROUND(N8,1)+P8 -> 5 | S8: =MROUND(O8,1)+Q8 -> 5 | T8: =SUM(S8,R8) -> 10 | U8: Grass | V8: Poison | W8: Dark | X8: Ground | Y8: Ivysaur | Z8: {=IF(ISBLANK(AK8),_xlfn.LET( _xlpm.nameBeforeSlash, IF(ISNUMBER(SEARCH("/", Y8)), LEFT(Y8, SEARCH("/", Y8)-1), Y8), _xlpm.matchRow, IFERROR(MATCH(_xlpm.nameBeforeSlash, AA:AA, 0), ""), _xlpm.difference, IF(_xlpm.matchRow="", "", ABS((R8 + S8) - (INDEX(R:R, _xlpm.matchRow) + INDEX(S:S, _xlpm.matchRow)))), _xlpm.category, IF(_xlpm.matchRow="", "", INDEX(AJ:AJ, _xlpm.matchRow)), _xlpm.adjustment, IF(_xlpm.matchRow="", "", IF(_xlpm.category="weak", 2, IF(_xlpm.category="moderate", 4, IF(_xlpm.category="strong", 8, IF(_xlpm.category="legendary", _xlpm.difference + 12, IF(_xlpm.category="warp", _xlpm.difference + 12, 0)))))), _xlpm.result, IF(_xlpm.matchRow="", "", IF(_xlpm.category="legendary", _xlpm.adjustment, _xlpm.difference + _xlpm.adjustment)), _xlpm.result ),IF(ISBLANK(Y8),"","Hidden"))} -> 8 | AA8: Bulbasaur | AC8: Vine Whip | AD8: =_xlfn.XLOOKUP(AC8,moves!A:A,moves!B:B) -> grass | AE8: =_xlfn.XLOOKUP(AC8,moves!A:A,moves!D:D) -> 2 | AF8: =_xlfn.XLOOKUP(AC8,moves!A:A,moves!E:E) -> Status symbols deal +1 damage. | AG8: 0 | AH8: 0 | AI8: =IF(ISNUMBER(SEARCH("Shiny ", AA8)), 1, 0) -> 0 | AJ8: weak | AL8: 0 | AM8: {=IF(AL8=1,1, IF(ISTEXT(AK8),1, IF(AO8>1,AM7, IF(AI8=1, IF(SUMPRODUCT((LEN($Y$2:$Y$4096)-LEN(SUBSTITUTE($Y$2:$Y$4096,AA8,"")))/LEN(AA8))>0,2,1), IF( SUMPRODUCT((LEN($Y$2:$Y$4096)-LEN(SUBSTITUTE($Y$2:$Y$4096,AA8,"")))/LEN(AA8)) - SUMPRODUCT((LEN($Y$2:$Y$4096)-LEN(SUBSTITUTE($Y$2:$Y$4096,"Alolan "&AA8,"")))/LEN("Alolan "&AA8)) - SUMPRODUCT((LEN($Y$2:$Y$4096)-LEN(SUBSTITUTE($Y$2:$Y$4096,"Galarian "&AA8,"")))/LEN("Galarian "&AA8)) - SUMPRODUCT((LEN($Y$2:$Y$4096)-LEN(SUBSTITUTE($Y$2:$Y$4096,"Hisuian "&AA8,"")))/LEN("Hisuian "&AA8)) - SUMPRODUCT((LEN($Y$2:$Y$4096)-LEN(SUBSTITUTE($Y$2:$Y$4096,"Paldean "&AA8,"")))/LEN("Paldean "&AA8)) >0,2,1) ))))} -> 1 | AN8: 0 | AO8: 0
A9: 1 | B9: Bulbasaur | C9: Grass | D9: Poison | E9: 45 | F9: 49 | G9: 49 | H9: 65 | I9: 65 | J9: 45 | K9: Seed Pokémon | L9: Forest | M9: Temperate | N9: 5.54 | O9: 5.22 | P9: -1 | R9: =MROUND(N9,1)+P9 -> 5 | S9: =MROUND(O9,1)+Q9 -> 5 | T9: =SUM(S9,R9) -> 10 | U9: Grass | V9: Poison | W9: Dark | X9: Ground | Y9: Ivysaur | Z9: {=IF(ISBLANK(AK9),_xlfn.LET( _xlpm.nameBeforeSlash, IF(ISNUMBER(SEARCH("/", Y9)), LEFT(Y9, SEARCH("/", Y9)-1), Y9), _xlpm.matchRow, IFERROR(MATCH(_xlpm.nameBeforeSlash, AA:AA, 0), ""), _xlpm.difference, IF(_xlpm.matchRow="", "", ABS((R9 + S9) - (INDEX(R:R, _xlpm.matchRow) + INDEX(S:S, _xlpm.matchRow)))), _xlpm.category, IF(_xlpm.matchRow="", "", INDEX(AJ:AJ, _xlpm.matchRow)), _xlpm.adjustment, IF(_xlpm.matchRow="", "", IF(_xlpm.category="weak", 2, IF(_xlpm.category="moderate", 4, IF(_xlpm.category="strong", 8, IF(_xlpm.category="legendary", _xlpm.difference + 12, IF(_xlpm.category="warp", _xlpm.difference + 12, 0)))))), _xlpm.result, IF(_xlpm.matchRow="", "", IF(_xlpm.category="legendary", _xlpm.adjustment, _xlpm.difference + _xlpm.adjustment)), _xlpm.result ),IF(ISBLANK(Y9),"","Hidden"))} -> 8 | AA9: Bulbasaur | AC9: Vine Whip | AD9: =_xlfn.XLOOKUP(AC9,moves!A:A,moves!B:B) -> grass | AE9: =_xlfn.XLOOKUP(AC9,moves!A:A,moves!D:D) -> 2 | AF9: =_xlfn.XLOOKUP(AC9,moves!A:A,moves!E:E) -> Status symbols deal +1 damage. | AG9: 0 | AH9: 0 | AI9: =IF(ISNUMBER(SEARCH("Shiny ", AA9)), 1, 0) -> 0 | AJ9: weak | AL9: 0 | AM9: {=IF(AL9=1,1, IF(ISTEXT(AK9),1, IF(AO9>1,AM8, IF(AI9=1, IF(SUMPRODUCT((LEN($Y$2:$Y$4096)-LEN(SUBSTITUTE($Y$2:$Y$4096,AA9,"")))/LEN(AA9))>0,2,1), IF( SUMPRODUCT((LEN($Y$2:$Y$4096)-LEN(SUBSTITUTE($Y$2:$Y$4096,AA9,"")))/LEN(AA9)) - SUMPRODUCT((LEN($Y$2:$Y$4096)-LEN(SUBSTITUTE($Y$2:$Y$4096,"Alolan "&AA9,"")))/LEN("Alolan "&AA9)) - SUMPRODUCT((LEN($Y$2:$Y$4096)-LEN(SUBSTITUTE($Y$2:$Y$4096,"Galarian "&AA9,"")))/LEN("Galarian "&AA9)) - SUMPRODUCT((LEN($Y$2:$Y$4096)-LEN(SUBSTITUTE($Y$2:$Y$4096,"Hisuian "&AA9,"")))/LEN("Hisuian "&AA9)) - SUMPRODUCT((LEN($Y$2:$Y$4096)-LEN(SUBSTITUTE($Y$2:$Y$4096,"Paldean "&AA9,"")))/LEN("Paldean "&AA9)) >0,2,1) ))))} -> 1 | AN9: 0 | AO9: 0
A10: 1 | B10: Bulbasaur | C10: Grass | D10: Poison | E10: 45 | F10: 49 | G10: 49 | H10: 65 | I10: 65 | J10: 45 | K10: Seed Pokémon | L10: Forest | M10: Temperate | N10: 5.54 | O10: 5.22 | P10: -1 | R10: =MROUND(N10,1)+P10 -> 5 | S10: =MROUND(O10,1)+Q10 -> 5 | T10: =SUM(S10,R10) -> 10 | U10: Grass | V10: Poison | W10: Dark | X10: Ground | Y10: Ivysaur | Z10: {=IF(ISBLANK(AK10),_xlfn.LET( _xlpm.nameBeforeSlash, IF(ISNUMBER(SEARCH("/", Y10)), LEFT(Y10, SEARCH("/", Y10)-1), Y10), _xlpm.matchRow, IFERROR(MATCH(_xlpm.nameBeforeSlash, AA:AA, 0), ""), _xlpm.difference, IF(_xlpm.matchRow="", "", ABS((R10 + S10) - (INDEX(R:R, _xlpm.matchRow) + INDEX(S:S, _xlpm.matchRow)))), _xlpm.category, IF(_xlpm.matchRow="", "", INDEX(AJ:AJ, _xlpm.matchRow)), _xlpm.adjustment, IF(_xlpm.matchRow="", "", IF(_xlpm.category="weak", 2, IF(_xlpm.category="moderate", 4, IF(_xlpm.category="strong", 8, IF(_xlpm.category="legendary", _xlpm.difference + 12, IF(_xlpm.category="warp", _xlpm.difference + 12, 0)))))), _xlpm.result, IF(_xlpm.matchRow="", "", IF(_xlpm.category="legendary", _xlpm.adjustment, _xlpm.difference + _xlpm.adjustment)), _xlpm.result ),IF(ISBLANK(Y10),"","Hidden"))} -> 8 | AA10: Bulbasaur | AC10: Vine Whip | AD10: =_xlfn.XLOOKUP(AC10,moves!A:A,moves!B:B) -> grass | AE10: =_xlfn.XLOOKUP(AC10,moves!A:A,moves!D:D) -> 2 | AF10: =_xlfn.XLOOKUP(AC10,moves!A:A,moves!E:E) -> Status symbols deal +1 damage. | AG10: 0 | AH10: 0 | AI10: =IF(ISNUMBER(SEARCH("Shiny ", AA10)), 1, 0) -> 0 | AJ10: weak | AL10: 0 | AM10: {=IF(AL10=1,1, IF(ISTEXT(AK10),1, IF(AO10>1,AM9, IF(AI10=1, IF(SUMPRODUCT((LEN($Y$2:$Y$4096)-LEN(SUBSTITUTE($Y$2:$Y$4096,AA10,"")))/LEN(AA10))>0,2,1), IF( SUMPRODUCT((LEN($Y$2:$Y$4096)-LEN(SUBSTITUTE($Y$2:$Y$4096,AA10,"")))/LEN(AA10)) - SUMPRODUCT((LEN($Y$2:$Y$4096)-LEN(SUBSTITUTE($Y$2:$Y$4096,"Alolan "&AA10,"")))/LEN("Alolan "&AA10)) - SUMPRODUCT((LEN($Y$2:$Y$4096)-LEN(SUBSTITUTE($Y$2:$Y$4096,"Galarian "&AA10,"")))/LEN("Galarian "&AA10)) - SUMPRODUCT((LEN($Y$2:$Y$4096)-LEN(SUBSTITUTE($Y$2:$Y$4096,"Hisuian "&AA10,"")))/LEN("Hisuian "&AA10)) - SUMPRODUCT((LEN($Y$2:$Y$4096)-LEN(SUBSTITUTE($Y$2:$Y$4096,"Paldean "&AA10,"")))/LEN("Paldean "&AA10)) >0,2,1) ))))} -> 1 | AN10: 0 | AO10: 0
A11: 1 | B11: Bulbasaur | C11: Grass | D11: Poison | E11: 45 | F11: 49 | G11: 49 | H11: 65 | I11: 65 | J11: 45 | K11: Seed Pokémon | L11: Forest | M11: Temperate | N11: 5.54 | O11: 5.22 | P11: -1 | R11: =MROUND(N11,1)+P11 -> 5 | S11: =MROUND(O11,1)+Q11 -> 5 | T11: =SUM(S11,R11) -> 10 | U11: Grass | V11: Poison | W11: Dark | X11: Ground | Y11: Ivysaur | Z11: {=IF(ISBLANK(AK11),_xlfn.LET( _xlpm.nameBeforeSlash, IF(ISNUMBER(SEARCH("/", Y11)), LEFT(Y11, SEARCH("/", Y11)-1), Y11), _xlpm.matchRow, IFERROR(MATCH(_xlpm.nameBeforeSlash, AA:AA, 0), ""), _xlpm.difference, IF(_xlpm.matchRow="", "", ABS((R11 + S11) - (INDEX(R:R, _xlpm.matchRow) + INDEX(S:S, _xlpm.matchRow)))), _xlpm.category, IF(_xlpm.matchRow="", "", INDEX(AJ:AJ, _xlpm.matchRow)), _xlpm.adjustment, IF(_xlpm.matchRow="", "", IF(_xlpm.category="weak", 2, IF(_xlpm.category="moderate", 4, IF(_xlpm.category="strong", 8, IF(_xlpm.category="legendary", _xlpm.difference + 12, IF(_xlpm.category="warp", _xlpm.difference + 12, 0)))))), _xlpm.result, IF(_xlpm.matchRow="", "", IF(_xlpm.category="legendary", _xlpm.adjustment, _xlpm.difference + _xlpm.adjustment)), _xlpm.result ),IF(ISBLANK(Y11),"","Hidden"))} -> 8 | AA11: Bulbasaur | AC11: Vine Whip | AD11: =_xlfn.XLOOKUP(AC11,moves!A:A,moves!B:B) -> grass | AE11: =_xlfn.XLOOKUP(AC11,moves!A:A,moves!D:D) -> 2 | AF11: =_xlfn.XLOOKUP(AC11,moves!A:A,moves!E:E) -> Status symbols deal +1 damage. | AG11: 0 | AH11: 0 | AI11: =IF(ISNUMBER(SEARCH("Shiny ", AA11)), 1, 0) -> 0 | AJ11: weak | AL11: 0 | AM11: {=IF(AL11=1,1, IF(ISTEXT(AK11),1, IF(AO11>1,AM10, IF(AI11=1, IF(SUMPRODUCT((LEN($Y$2:$Y$4096)-LEN(SUBSTITUTE($Y$2:$Y$4096,AA11,"")))/LEN(AA11))>0,2,1), IF( SUMPRODUCT((LEN($Y$2:$Y$4096)-LEN(SUBSTITUTE($Y$2:$Y$4096,AA11,"")))/LEN(AA11)) - SUMPRODUCT((LEN($Y$2:$Y$4096)-LEN(SUBSTITUTE($Y$2:$Y$4096,"Alolan "&AA11,"")))/LEN("Alolan "&AA11)) - SUMPRODUCT((LEN($Y$2:$Y$4096)-LEN(SUBSTITUTE($Y$2:$Y$4096,"Galarian "&AA11,"")))/LEN("Galarian "&AA11)) - SUMPRODUCT((LEN($Y$2:$Y$4096)-LEN(SUBSTITUTE($Y$2:$Y$4096,"Hisuian "&AA11,"")))/LEN("Hisuian "&AA11)) - SUMPRODUCT((LEN($Y$2:$Y$4096)-LEN(SUBSTITUTE($Y$2:$Y$4096,"Paldean "&AA11,"")))/LEN("Paldean "&AA11)) >0,2,1) ))))} -> 1 | AN11: 0 | AO11: 0
A12: 1 | B12: Bulbasaur | C12: Grass | D12: Poison | E12: 45 | F12: 49 | G12: 49 | H12: 65 | I12: 65 | J12: 45 | K12: Seed Pokémon | L12: Forest | M12: Temperate | N12: 5.54 | O12: 5.22 | P12: -1 | R12: =MROUND(N12,1)+P12 -> 5 | S12: =MROUND(O12,1)+Q12 -> 5 | T12: =SUM(S12,R12) -> 10 | U12: Grass | V12: Poison | W12: Dark | X12: Ground | Y12: Ivysaur | Z12: {=IF(ISBLANK(AK12),_xlfn.LET( _xlpm.nameBeforeSlash, IF(ISNUMBER(SEARCH("/", Y12)), LEFT(Y12, SEARCH("/", Y12)-1), Y12), _xlpm.matchRow, IFERROR(MATCH(_xlpm.nameBeforeSlash, AA:AA, 0), ""), _xlpm.difference, IF(_xlpm.matchRow="", "", ABS((R12 + S12) - (INDEX(R:R, _xlpm.matchRow) + INDEX(S:S, _xlpm.matchRow)))), _xlpm.category, IF(_xlpm.matchRow="", "", INDEX(AJ:AJ, _xlpm.matchRow)), _xlpm.adjustment, IF(_xlpm.matchRow="", "", IF(_xlpm.category="weak", 2, IF(_xlpm.category="moderate", 4, IF(_xlpm.category="strong", 8, IF(_xlpm.category="legendary", _xlpm.difference + 12, IF(_xlpm.category="warp", _xlpm.difference + 12, 0)))))), _xlpm.result, IF(_xlpm.matchRow="", "", IF(_xlpm.category="legendary", _xlpm.adjustment, _xlpm.difference + _xlpm.adjustment)), _xlpm.result ),IF(ISBLANK(Y12),"","Hidden"))} -> 8 | AA12: Bulbasaur | AC12: Vine Whip | AD12: =_xlfn.XLOOKUP(AC12,moves!A:A,moves!B:B) -> grass | AE12: =_xlfn.XLOOKUP(AC12,moves!A:A,moves!D:D) -> 2 | AF12: =_xlfn.XLOOKUP(AC12,moves!A:A,moves!E:E) -> Status symbols deal +1 damage. | AG12: 0 | AH12: 0 | AI12: =IF(ISNUMBER(SEARCH("Shiny ", AA12)), 1, 0) -> 0 | AJ12: weak | AL12: 0 | AM12: {=IF(AL12=1,1, IF(ISTEXT(AK12),1, IF(AO12>1,AM11, IF(AI12=1, IF(SUMPRODUCT((LEN($Y$2:$Y$4096)-LEN(SUBSTITUTE($Y$2:$Y$4096,AA12,"")))/LEN(AA12))>0,2,1), IF( SUMPRODUCT((LEN($Y$2:$Y$4096)-LEN(SUBSTITUTE($Y$2:$Y$4096,AA12,"")))/LEN(AA12)) - SUMPRODUCT((LEN($Y$2:$Y$4096)-LEN(SUBSTITUTE($Y$2:$Y$4096,"Alolan "&AA12,"")))/LEN("Alolan "&AA12)) - SUMPRODUCT((LEN($Y$2:$Y$4096)-LEN(SUBSTITUTE($Y$2:$Y$4096,"Galarian "&AA12,"")))/LEN("Galarian "&AA12)) - SUMPRODUCT((LEN($Y$2:$Y$4096)-LEN(SUBSTITUTE($Y$2:$Y$4096,"Hisuian "&AA12,"")))/LEN("Hisuian "&AA12)) - SUMPRODUCT((LEN($Y$2:$Y$4096)-LEN(SUBSTITUTE($Y$2:$Y$4096,"Paldean "&AA12,"")))/LEN("Paldean "&AA12)) >0,2,1) ))))} -> 1 | AN12: 0 | AO12: 0
A13: 1-shiny | B13: Bulbasaur | C13: Grass | D13: Poison | E13: 45 | F13: 49 | G13: 49 | H13: 65 | I13: 65 | J13: 45 | K13: Seed Pokémon | L13: Forest | M13: Temperate | N13: 5.54 | O13: 5.22 | P13: -1 | R13: =MROUND(N13,1)+P13 -> 5 | S13: =MROUND(O13,1)+Q13 -> 5 | T13: =SUM(S13,R13) -> 10 | U13: Grass | V13: Poison | W13: Dark | X13: Ground | Y13: Shiny Ivysaur | Z13: {=IF(ISBLANK(AK13),_xlfn.LET( _xlpm.nameBeforeSlash, IF(ISNUMBER(SEARCH("/", Y13)), LEFT(Y13, SEARCH("/", Y13)-1), Y13), _xlpm.matchRow, IFERROR(MATCH(_xlpm.nameBeforeSlash, AA:AA, 0), ""), _xlpm.difference, IF(_xlpm.matchRow="", "", ABS((R13 + S13) - (INDEX(R:R, _xlpm.matchRow) + INDEX(S:S, _xlpm.matchRow)))), _xlpm.category, IF(_xlpm.matchRow="", "", INDEX(AJ:AJ, _xlpm.matchRow)), _xlpm.adjustment, IF(_xlpm.matchRow="", "", IF(_xlpm.category="weak", 2, IF(_xlpm.category="moderate", 4, IF(_xlpm.category="strong", 8, IF(_xlpm.category="legendary", _xlpm.difference + 12, IF(_xlpm.category="warp", _xlpm.difference + 12, 0)))))), _xlpm.result, IF(_xlpm.matchRow="", "", IF(_xlpm.category="legendary", _xlpm.adjustment, _xlpm.difference + _xlpm.adjustment)), _xlpm.result ),IF(ISBLANK(Y13),"","Hidden"))} -> 8 | AA13: Shiny Bulbasaur | AC13: Leech Seed | AD13: =_xlfn.XLOOKUP(AC13,moves!A:A,moves!B:B) -> grass | AE13: =_xlfn.XLOOKUP(AC13,moves!A:A,moves!D:D) -> 1 | AF13: =_xlfn.XLOOKUP(AC13,moves!A:A,moves!E:E) -> At the end of the target's turns: The target takes 1 damage and the user Heals 1. | AG13: 1 | AH13: 0 | AI13: =IF(ISNUMBER(SEARCH("Shiny ", AA13)), 1, 0) -> 1 | AJ13: weak | AL13: 0 | AM13: {=IF(AL13=1,1, IF(ISTEXT(AK13),1, IF(AO13>1,AM12, IF(AI13=1, IF(SUMPRODUCT((LEN($Y$2:$Y$4096)-LEN(SUBSTITUTE($Y$2:$Y$4096,AA13,"")))/LEN(AA13))>0,2,1), IF( SUMPRODUCT((LEN($Y$2:$Y$4096)-LEN(SUBSTITUTE($Y$2:$Y$4096,AA13,"")))/LEN(AA13)) - SUMPRODUCT((LEN($Y$2:$Y$4096)-LEN(SUBSTITUTE($Y$2:$Y$4096,"Alolan "&AA13,"")))/LEN("Alolan "&AA13)) - SUMPRODUCT((LEN($Y$2:$Y$4096)-LEN(SUBSTITUTE($Y$2:$Y$4096,"Galarian "&AA13,"")))/LEN("Galarian "&AA13)) - SUMPRODUCT((LEN($Y$2:$Y$4096)-LEN(SUBSTITUTE($Y$2:$Y$4096,"Hisuian "&AA13,"")))/LEN("Hisuian "&AA13)) - SUMPRODUCT((LEN($Y$2:$Y$4096)-LEN(SUBSTITUTE($Y$2:$Y$4096,"Paldean "&AA13,"")))/LEN("Paldean "&AA13)) >0,2,1) ))))} -> 1 | AN13: 0 | AO13: 0
A14: 2 | B14: Ivysaur | C14: Grass | D14: Poison | E14: 60 | F14: 62 | G14: 63 | H14: 80 | I14: 80 | J14: 60 | K14: Seed Pokémon | L14: Forest | M14: Temperate | N14: 7.02 | O14: 6.69 | R14: =MROUND(N14,1)+P14 -> 7 | S14: =MROUND(O14,1)+Q14 -> 7 | T14: =SUM(S14,R14) -> 14 | U14: Grass | V14: Poison | W14: Dark | X14: Ground | Y14: Venusaur | Z14: {=IF(ISBLANK(AK14),_xlfn.LET( _xlpm.nameBeforeSlash, IF(ISNUMBER(SEARCH("/", Y14)), LEFT(Y14, SEARCH("/", Y14)-1), Y14), _xlpm.matchRow, IFERROR(MATCH(_xlpm.nameBeforeSlash, AA:AA, 0), ""), _xlpm.difference, IF(_xlpm.matchRow="", "", ABS((R14 + S14) - (INDEX(R:R, _xlpm.matchRow) + INDEX(S:S, _xlpm.matchRow)))), _xlpm.category, IF(_xlpm.matchRow="", "", INDEX(AJ:AJ, _xlpm.matchRow)), _xlpm.adjustment, IF(_xlpm.matchRow="", "", IF(_xlpm.category="weak", 2, IF(_xlpm.category="moderate", 4, IF(_xlpm.category="strong", 8, IF(_xlpm.category="legendary", _xlpm.difference + 12, IF(_xlpm.category="warp", _xlpm.difference + 12, 0)))))), _xlpm.result, IF(_xlpm.matchRow="", "", IF(_xlpm.category="legendary", _xlpm.adjustment, _xlpm.difference + _xlpm.adjustment)), _xlpm.result ),IF(ISBLANK(Y14),"","Hidden"))} -> 14 | AA14: Ivysaur | AC14: Mud Bomb | AD14: =_xlfn.XLOOKUP(AC14,moves!A:A,moves!B:B) -> ground | AE14: =_xlfn.XLOOKUP(AC14,moves!A:A,moves!D:D) -> 3 | AF14: =_xlfn.XLOOKUP(AC14,moves!A:A,moves!E:E) -> When the target next attacks: Status symbols deal -1 damage. | AG14: 0 | AH14: 0 | AI14: =IF(ISNUMBER(SEARCH("Shiny ", AA14)), 1, 0) -> 0 | AJ14: moderate | AL14: 0 | AM14: {=IF(AL14=1,1, IF(ISTEXT(AK14),1, IF(AO14>1,AM13, IF(AI14=1, IF(SUMPRODUCT((LEN($Y$2:$Y$4096)-LEN(SUBSTITUTE($Y$2:$Y$4096,AA14,"")))/LEN(AA14))>0,2,1), IF( SUMPRODUCT((LEN($Y$2:$Y$4096)-LEN(SUBSTITUTE($Y$2:$Y$4096,AA14,"")))/LEN(AA14)) - SUMPRODUCT((LEN($Y$2:$Y$4096)-LEN(SUBSTITUTE($Y$2:$Y$4096,"Alolan "&AA14,"")))/LEN("Alolan "&AA14)) - SUMPRODUCT((LEN($Y$2:$Y$4096)-LEN(SUBSTITUTE($Y$2:$Y$4096,"Galarian "&AA14,"")))/LEN("Galarian "&AA14)) - SUMPRODUCT((LEN($Y$2:$Y$4096)-LEN(SUBSTITUTE($Y$2:$Y$4096,"Hisuian "&AA14,"")))/LEN("Hisuian "&AA14)) - SUMPRODUCT((LEN($Y$2:$Y$4096)-LEN(SUBSTITUTE($Y$2:$Y$4096,"Paldean "&AA14,"")))/LEN("Paldean "&AA14)) >0,2,1) ))))} -> 2 | AN14: 0 | AO14: 0
A15: 2-shiny | B15: Ivysaur | C15: Grass | D15: Poison | E15: 60 | F15: 62 | G15: 63 | H15: 80 | I15: 80 | J15: 60 | K15: Seed Pokémon | L15: Forest | M15: Temperate | N15: 7.02 | O15: 6.69 | R15: =MROUND(N15,1)+P15 -> 7 | S15: =MROUND(O15,1)+Q15 -> 7 | T15: =SUM(S15,R15) -> 14 | U15: Grass | V15: Poison | W15: Dark | X15: Ground | Y15: Shiny Venusaur | Z15: {=IF(ISBLANK(AK15),_xlfn.LET( _xlpm.nameBeforeSlash, IF(ISNUMBER(SEARCH("/", Y15)), LEFT(Y15, SEARCH("/", Y15)-1), Y15), _xlpm.matchRow, IFERROR(MATCH(_xlpm.nameBeforeSlash, AA:AA, 0), ""), _xlpm.difference, IF(_xlpm.matchRow="", "", ABS((R15 + S15) - (INDEX(R:R, _xlpm.matchRow) + INDEX(S:S, _xlpm.matchRow)))), _xlpm.category, IF(_xlpm.matchRow="", "", INDEX(AJ:AJ, _xlpm.matchRow)), _xlpm.adjustment, IF(_xlpm.matchRow="", "", IF(_xlpm.category="weak", 2, IF(_xlpm.category="moderate", 4, IF(_xlpm.category="strong", 8, IF(_xlpm.category="legendary", _xlpm.difference + 12, IF(_xlpm.category="warp", _xlpm.difference + 12, 0)))))), _xlpm.result, IF(_xlpm.matchRow="", "", IF(_xlpm.category="legendary", _xlpm.adjustment, _xlpm.difference + _xlpm.adjustment)), _xlpm.result ),IF(ISBLANK(Y15),"","Hidden"))} -> 14 | AA15: Shiny Ivysaur | AC15: Seed Bomb | AD15: =_xlfn.XLOOKUP(AC15,moves!A:A,moves!B:B) -> grass | AE15: =_xlfn.XLOOKUP(AC15,moves!A:A,moves!D:D) -> 4 | AF15: =_xlfn.XLOOKUP(AC15,moves!A:A,moves!E:E) -> Every 2 regular hits deal +1 damage. | AG15: 0 | AH15: 0 | AI15: =IF(ISNUMBER(SEARCH("Shiny ", AA15)), 1, 0) -> 1 | AJ15: moderate | AL15: 0 | AM15: {=IF(AL15=1,1, IF(ISTEXT(AK15),1, IF(AO15>1,AM14, IF(AI15=1, IF(SUMPRODUCT((LEN($Y$2:$Y$4096)-LEN(SUBSTITUTE($Y$2:$Y$4096,AA15,"")))/LEN(AA15))>0,2,1), IF( SUMPRODUCT((LEN($Y$2:$Y$4096)-LEN(SUBSTITUTE($Y$2:$Y$4096,AA15,"")))/LEN(AA15)) - SUMPRODUCT((LEN($Y$2:$Y$4096)-LEN(SUBSTITUTE($Y$2:$Y$4096,"Alolan "&AA15,"")))/LEN("Alolan "&AA15)) - SUMPRODUCT((LEN($Y$2:$Y$4096)-LEN(SUBSTITUTE($Y$2:$Y$4096,"Galarian "&AA15,"")))/LEN("Galarian "&AA15)) - SUMPRODUCT((LEN($Y$2:$Y$4096)-LEN(SUBSTITUTE($Y$2:$Y$4096,"Hisuian "&AA15,"")))/LEN("Hisuian "&AA15)) - SUMPRODUCT((LEN($Y$2:$Y$4096)-LEN(SUBSTITUTE($Y$2:$Y$4096,"Paldean "&AA15,"")))/LEN("Paldean "&AA15)) >0,2,1) ))))} -> 2 | AN15: 0 | AO15: 0
A16: 3 | B16: Venusaur | C16: Grass | D16: Poison | E16: 80 | F16: 82 | G16: 83 | H16: 100 | I16: 100 | J16: 80 | K16: Seed Pokémon | L16: Forest | M16: Temperate | N16: 9.02 | O16: 8.69 | Q16: 2 | R16: =MROUND(N16,1)+P16 -> 9 | S16: =MROUND(O16,1)+Q16 -> 11 | T16: =SUM(S16,R16) -> 20 | U16: Grass | V16: Poison | W16: Dark | X16: Ground | Z16: {=IF(ISBLANK(AK16),_xlfn.LET( _xlpm.nameBeforeSlash, IF(ISNUMBER(SEARCH("/", Y16)), LEFT(Y16, SEARCH("/", Y16)-1), Y16), _xlpm.matchRow, IFERROR(MATCH(_xlpm.nameBeforeSlash, AA:AA, 0), ""), _xlpm.difference, IF(_xlpm.matchRow="", "", ABS((R16 + S16) - (INDEX(R:R, _xlpm.matchRow) + INDEX(S:S, _xlpm.matchRow)))), _xlpm.category, IF(_xlpm.matchRow="", "", INDEX(AJ:AJ, _xlpm.matchRow)), _xlpm.adjustment, IF(_xlpm.matchRow="", "", IF(_xlpm.category="weak", 2, IF(_xlpm.category="moderate", 4, IF(_xlpm.category="strong", 8, IF(_xlpm.category="legendary", _xlpm.difference + 12, IF(_xlpm.category="warp", _xlpm.difference + 12, 0)))))), _xlpm.result, IF(_xlpm.matchRow="", "", IF(_xlpm.category="legendary", _xlpm.adjustment, _xlpm.difference + _xlpm.adjustment)), _xlpm.result ),IF(ISBLANK(Y16),"","Hidden"))} | AA16: Venusaur | AC16: Solar Beam | AD16: =_xlfn.XLOOKUP(AC16,moves!A:A,moves!B:B) -> grass | AE16: =_xlfn.XLOOKUP(AC16,moves!A:A,moves!D:D) -> 6 | AF16: =_xlfn.XLOOKUP(AC16,moves!A:A,moves!E:E) -> If this move is used during Harsh Sunlight: Ignore the delay. If this move is used during Rain, Hail, or Sandstorm: Decrease attack strength by 3. | AG16: 0 | AH16: 0 | AI16: =IF(ISNUMBER(SEARCH("Shiny ", AA16)), 1, 0) -> 0 | AJ16: strong | AL16: 0 | AM16: {=IF(AL16=1,1, IF(ISTEXT(AK16),1, IF(AO16>1,AM15, IF(AI16=1, IF(SUMPRODUCT((LEN($Y$2:$Y$4096)-LEN(SUBSTITUTE($Y$2:$Y$4096,AA16,"")))/LEN(AA16))>0,2,1), IF( SUMPRODUCT((LEN($Y$2:$Y$4096)-LEN(SUBSTITUTE($Y$2:$Y$4096,AA16,"")))/LEN(AA16)) - SUMPRODUCT((LEN($Y$2:$Y$4096)-LEN(SUBSTITUTE($Y$2:$Y$4096,"Alolan "&AA16,"")))/LEN("Alolan "&AA16)) - SUMPRODUCT((LEN($Y$2:$Y$4096)-LEN(SUBSTITUTE($Y$2:$Y$4096,"Galarian "&AA16,"")))/LEN("Galarian "&AA16)) - SUMPRODUCT((LEN($Y$2:$Y$4096)-LEN(SUBSTITUTE($Y$2:$Y$4096,"Hisuian "&AA16,"")))/LEN("Hisuian "&AA16)) - SUMPRODUCT((LEN($Y$2:$Y$4096)-LEN(SUBSTITUTE($Y$2:$Y$4096,"Paldean "&AA16,"")))/LEN("Paldean "&AA16)) >0,2,1) ))))} -> 2 | AN16: 0 | AO16: 1
A17: 3-m | B17: Venusaur | C17: Grass | D17: Poison | E17: 80 | F17: 100 | G17: 123 | H17: 122 | I17: 120 | J17: 80 | K17: Seed Pokémon | L17: blank | M17: Mega | N17: 10.3 | O17: 10.49 | P17: 1 | Q17: 3 | R17: =MROUND(N17,1)+P17 -> 11 | S17: =MROUND(O17,1)+Q17 -> 13 | T17: =SUM(S17,R17) -> 24 | U17: Grass | V17: Poison | W17: Dark | X17: Ground | Z17: {=IF(ISBLANK(AK17),_xlfn.LET( _xlpm.nameBeforeSlash, IF(ISNUMBER(SEARCH("/", Y17)), LEFT(Y17, SEARCH("/", Y17)-1), Y17), _xlpm.matchRow, IFERROR(MATCH(_xlpm.nameBeforeSlash, AA:AA, 0), ""), _xlpm.difference, IF(_xlpm.matchRow="", "", ABS((R17 + S17) - (INDEX(R:R, _xlpm.matchRow) + INDEX(S:S, _xlpm.matchRow)))), _xlpm.category, IF(_xlpm.matchRow="", "", INDEX(AJ:AJ, _xlpm.matchRow)), _xlpm.adjustment, IF(_xlpm.matchRow="", "", IF(_xlpm.category="weak", 2, IF(_xlpm.category="moderate", 4, IF(_xlpm.category="strong", 8, IF(_xlpm.category="legendary", _xlpm.difference + 12, IF(_xlpm.category="warp", _xlpm.difference + 12, 0)))))), _xlpm.result, IF(_xlpm.matchRow="", "", IF(_xlpm.category="legendary", _xlpm.adjustment, _xlpm.difference + _xlpm.adjustment)), _xlpm.result ),IF(ISBLANK(Y17),"","Hidden"))} | AA17: Mega Venusaur | AB17: Mega Form | AC17: Petal Blizzard | AD17: =_xlfn.XLOOKUP(AC17,moves!A:A,moves!B:B) -> grass | AE17: =_xlfn.XLOOKUP(AC17,moves!A:A,moves!D:D) -> 5 | AF17: =_xlfn.XLOOKUP(AC17,moves!A:A,moves!E:E) | AG17: 0 | AH17: 0 | AI17: =IF(ISNUMBER(SEARCH("Shiny ", AA17)), 1, 0) -> 0 | AJ17: strong | AL17: 0 | AM17: {=IF(AL17=1,1, IF(ISTEXT(AK17),1, IF(AO17>1,AM16, IF(AI17=1, IF(SUMPRODUCT((LEN($Y$2:$Y$4096)-LEN(SUBSTITUTE($Y$2:$Y$4096,AA17,"")))/LEN(AA17))>0,2,1), IF( SUMPRODUCT((LEN($Y$2:$Y$4096)-LEN(SUBSTITUTE($Y$2:$Y$4096,AA17,"")))/LEN(AA17)) - SUMPRODUCT((LEN($Y$2:$Y$4096)-LEN(SUBSTITUTE($Y$2:$Y$4096,"Alolan "&AA17,"")))/LEN("Alolan "&AA17)) - SUMPRODUCT((LEN($Y$2:$Y$4096)-LEN(SUBSTITUTE($Y$2:$Y$4096,"Galarian "&AA17,"")))/LEN("Galarian "&AA17)) - SUMPRODUCT((LEN($Y$2:$Y$4096)-LEN(SUBSTITUTE($Y$2:$Y$4096,"Hisuian "&AA17,"")))/LEN("Hisuian "&AA17)) - SUMPRODUCT((LEN($Y$2:$Y$4096)-LEN(SUBSTITUTE($Y$2:$Y$4096,"Paldean "&AA17,"")))/LEN("Paldean "&AA17)) >0,2,1) ))))} -> 2 | AN17: 0 | AO17: 2
A18: 3-gm | B18: Venusaur | C18: Grass | D18: Poison | E18: 80 | F18: 100 | G18: 123 | H18: 122 | I18: 120 | J18: 80 | K18: Seed Pokémon | L18: blank | M18: Gigantamax | N18: 10.3 | O18: 10.49 | P18: -1 | Q18: 11 | R18: =MROUND(N18,1)+P18 -> 9 | S18: =MROUND(O18,1)+Q18 -> 21 | T18: =SUM(S18,R18) -> 30 | U18: Grass | V18: Poison | W18: Dark | X18: Ground | Z18: {=IF(ISBLANK(AK18),_xlfn.LET( _xlpm.nameBeforeSlash, IF(ISNUMBER(SEARCH("/", Y18)), LEFT(Y18, SEARCH("/", Y18)-1), Y18), _xlpm.matchRow, IFERROR(MATCH(_xlpm.nameBeforeSlash, AA:AA, 0), ""), _xlpm.difference, IF(_xlpm.matchRow="", "", ABS((R18 + S18) - (INDEX(R:R, _xlpm.matchRow) + INDEX(S:S, _xlpm.matchRow)))), _xlpm.category, IF(_xlpm.matchRow="", "", INDEX(AJ:AJ, _xlpm.matchRow)), _xlpm.adjustment, IF(_xlpm.matchRow="", "", IF(_xlpm.category="weak", 2, IF(_xlpm.category="moderate", 4, IF(_xlpm.category="strong", 8, IF(_xlpm.category="legendary", _xlpm.difference + 12, IF(_xlpm.category="warp", _xlpm.difference + 12, 0)))))), _xlpm.result, IF(_xlpm.matchRow="", "", IF(_xlpm.category="legendary", _xlpm.adjustment, _xlpm.difference + _xlpm.adjustment)), _xlpm.result ),IF(ISBLANK(Y18),"","Hidden"))} | AA18: Gigantamax Venusaur | AB18: Gigantamax Form | AC18: G-Max Vine Lash | AD18: =_xlfn.XLOOKUP(AC18,moves!A:A,moves!B:B) -> grass | AE18: =_xlfn.XLOOKUP(AC18,moves!A:A,moves!D:D) -> 5 | AF18: =_xlfn.XLOOKUP(AC18,moves!A:A,moves!E:E) -> All opposing non Grass-type active Pokémon take 2 damage at the end of their turns. | AG18: 0 | AH18: 0 | AI18: =IF(ISNUMBER(SEARCH("Shiny ", AA18)), 1, 0) -> 0 | AJ18: strong | AL18: 0 | AM18: {=IF(AL18=1,1, IF(ISTEXT(AK18),1, IF(AO18>1,AM17, IF(AI18=1, IF(SUMPRODUCT((LEN($Y$2:$Y$4096)-LEN(SUBSTITUTE($Y$2:$Y$4096,AA18,"")))/LEN(AA18))>0,2,1), IF( SUMPRODUCT((LEN($Y$2:$Y$4096)-LEN(SUBSTITUTE($Y$2:$Y$4096,AA18,"")))/LEN(AA18)) - SUMPRODUCT((LEN($Y$2:$Y$4096)-LEN(SUBSTITUTE($Y$2:$Y$4096,"Alolan "&AA18,"")))/LEN("Alolan "&AA18)) - SUMPRODUCT((LEN($Y$2:$Y$4096)-LEN(SUBSTITUTE($Y$2:$Y$4096,"Galarian "&AA18,"")))/LEN("Galarian "&AA18)) - SUMPRODUCT((LEN($Y$2:$Y$4096)-LEN(SUBSTITUTE($Y$2:$Y$4096,"Hisuian "&AA18,"")))/LEN("Hisuian "&AA18)) - SUMPRODUCT((LEN($Y$2:$Y$4096)-LEN(SUBSTITUTE($Y$2:$Y$4096,"Paldean "&AA18,"")))/LEN("Paldean "&AA18)) >0,2,1) ))))} -> 2 | AN18: 0 | AO18: 3
A19: 3-shiny | B19: Venusaur | C19: Grass | D19: Poison | E19: 80 | F19: 82 | G19: 83 | H19: 100 | I19: 100 | J19: 80 | K19: Seed Pokémon | L19: Forest | M19: Temperate | N19: 9.02 | O19: 8.69 | Q19: 2 | R19: =MROUND(N19,1)+P19 -> 9 | S19: =MROUND(O19,1)+Q19 -> 11 | T19: =SUM(S19,R19) -> 20 | U19: Grass | V19: Poison | W19: Dark | X19: Ground | Z19: {=IF(ISBLANK(AK19),_xlfn.LET( _xlpm.nameBeforeSlash, IF(ISNUMBER(SEARCH("/", Y19)), LEFT(Y19, SEARCH("/", Y19)-1), Y19), _xlpm.matchRow, IFERROR(MATCH(_xlpm.nameBeforeSlash, AA:AA, 0), ""), _xlpm.difference, IF(_xlpm.matchRow="", "", ABS((R19 + S19) - (INDEX(R:R, _xlpm.matchRow) + INDEX(S:S, _xlpm.matchRow)))), _xlpm.category, IF(_xlpm.matchRow="", "", INDEX(AJ:AJ, _xlpm.matchRow)), _xlpm.adjustment, IF(_xlpm.matchRow="", "", IF(_xlpm.category="weak", 2, IF(_xlpm.category="moderate", 4, IF(_xlpm.category="strong", 8, IF(_xlpm.category="legendary", _xlpm.difference + 12, IF(_xlpm.category="warp", _xlpm.difference + 12, 0)))))), _xlpm.result, IF(_xlpm.matchRow="", "", IF(_xlpm.category="legendary", _xlpm.adjustment, _xlpm.difference + _xlpm.adjustment)), _xlpm.result ),IF(ISBLANK(Y19),"","Hidden"))} | AA19: Shiny Venusaur | AC19: Pollen Hazard | AD19: =_xlfn.XLOOKUP(AC19,moves!A:A,moves!B:B) -> grass | AE19: =_xlfn.XLOOKUP(AC19,moves!A:A,moves!D:D) -> 4 | AF19: =_xlfn.XLOOKUP(AC19,moves!A:A,moves!E:E) -> Inflict the Confused, Burned, and Poisoned status on the target, simultaneously. | AG19: 0 | AH19: 0 | AI19: =IF(ISNUMBER(SEARCH("Shiny ", AA19)), 1, 0) -> 1 | AJ19: strong | AL19: 0 | AM19: {=IF(AL19=1,1, IF(ISTEXT(AK19),1, IF(AO19>1,AM18, IF(AI19=1, IF(SUMPRODUCT((LEN($Y$2:$Y$4096)-LEN(SUBSTITUTE($Y$2:$Y$4096,AA19,"")))/LEN(AA19))>0,2,1), IF( SUMPRODUCT((LEN($Y$2:$Y$4096)-LEN(SUBSTITUTE($Y$2:$Y$4096,AA19,"")))/LEN(AA19)) - SUMPRODUCT((LEN($Y$2:$Y$4096)-LEN(SUBSTITUTE($Y$2:$Y$4096,"Alolan "&AA19,"")))/LEN("Alolan "&AA19)) - SUMPRODUCT((LEN($Y$2:$Y$4096)-LEN(SUBSTITUTE($Y$2:$Y$4096,"Galarian "&AA19,"")))/LEN("Galarian "&AA19)) - SUMPRODUCT((LEN($Y$2:$Y$4096)-LEN(SUBSTITUTE($Y$2:$Y$4096,"Hisuian "&AA19,"")))/LEN("Hisuian "&AA19)) - SUMPRODUCT((LEN($Y$2:$Y$4096)-LEN(SUBSTITUTE($Y$2:$Y$4096,"Paldean "&AA19,"")))/LEN("Paldean "&AA19)) >0,2,1) ))))} -> 2 | AN19: 0 | AO19: 1
A20: 3-m-shiny | B20: Venusaur | C20: Grass | D20: Poison | E20: 80 | F20: 100 | G20: 123 | H20: 122 | I20: 120 | J20: 80 | K20: Seed Pokémon | L20: blank | M20: Mega | N20: 10.3 | O20: 10.49 | P20: 1 | Q20: 3 | R20: =MROUND(N20,1)+P20 -> 11 | S20: =MROUND(O20,1)+Q20 -> 13 | T20: =SUM(S20,R20) -> 24 | U20: Grass | V20: Poison | W20: Dark | X20: Ground | Z20: {=IF(ISBLANK(AK20),_xlfn.LET( _xlpm.nameBeforeSlash, IF(ISNUMBER(SEARCH("/", Y20)), LEFT(Y20, SEARCH("/", Y20)-1), Y20), _xlpm.matchRow, IFERROR(MATCH(_xlpm.nameBeforeSlash, AA:AA, 0), ""), _xlpm.difference, IF(_xlpm.matchRow="", "", ABS((R20 + S20) - (INDEX(R:R, _xlpm.matchRow) + INDEX(S:S, _xlpm.matchRow)))), _xlpm.category, IF(_xlpm.matchRow="", "", INDEX(AJ:AJ, _xlpm.matchRow)), _xlpm.adjustment, IF(_xlpm.matchRow="", "", IF(_xlpm.category="weak", 2, IF(_xlpm.category="moderate", 4, IF(_xlpm.category="strong", 8, IF(_xlpm.category="legendary", _xlpm.difference + 12, IF(_xlpm.category="warp", _xlpm.difference + 12, 0)))))), _xlpm.result, IF(_xlpm.matchRow="", "", IF(_xlpm.category="legendary", _xlpm.adjustment, _xlpm.difference + _xlpm.adjustment)), _xlpm.result ),IF(ISBLANK(Y20),"","Hidden"))} | AA20: Shiny Mega Venusaur | AB20: Mega Form | AC20: Bloom Buster | AD20: =_xlfn.XLOOKUP(AC20,moves!A:A,moves!B:B) -> grass | AE20: =_xlfn.XLOOKUP(AC20,moves!A:A,moves!D:D) -> 5 | AF20: =_xlfn.XLOOKUP(AC20,moves!A:A,moves!E:E) -> If 2 or more status symbols are rolled: Deal 2 damage to all Pokémon in the target party that is not the target. | AG20: 0 | AH20: 0 | AI20: =IF(ISNUMBER(SEARCH("Shiny ", AA20)), 1, 0) -> 1 | AJ20: strong | AL20: 0 | AM20: {=IF(AL20=1,1, IF(ISTEXT(AK20),1, IF(AO20>1,AM19, IF(AI20=1, IF(SUMPRODUCT((LEN($Y$2:$Y$4096)-LEN(SUBSTITUTE($Y$2:$Y$4096,AA20,"")))/LEN(AA20))>0,2,1), IF( SUMPRODUCT((LEN($Y$2:$Y$4096)-LEN(SUBSTITUTE($Y$2:$Y$4096,AA20,"")))/LEN(AA20)) - SUMPRODUCT((LEN($Y$2:$Y$4096)-LEN(SUBSTITUTE($Y$2:$Y$4096,"Alolan "&AA20,"")))/LEN("Alolan "&AA20)) - SUMPRODUCT((LEN($Y$2:$Y$4096)-LEN(SUBSTITUTE($Y$2:$Y$4096,"Galarian "&AA20,"")))/LEN("Galarian "&AA20)) - SUMPRODUCT((LEN($Y$2:$Y$4096)-LEN(SUBSTITUTE($Y$2:$Y$4096,"Hisuian "&AA20,"")))/LEN("Hisuian "&AA20)) - SUMPRODUCT((LEN($Y$2:$Y$4096)-LEN(SUBSTITUTE($Y$2:$Y$4096,"Paldean "&AA20,"")))/LEN("Paldean "&AA20)) >0,2,1) ))))} -> 2 | AN20: 0 | AO20: 2
A21: 3-gm-shiny | B21: Venusaur | C21: Grass | D21: Poison | E21: 80 | F21: 100 | G21: 123 | H21: 122 | I21: 120 | J21: 80 | K21: Seed Pokémon | L21: blank | M21: Gigantamax | N21: 10.3 | O21: 10.49 | P21: -1 | Q21: 11 | R21: =MROUND(N21,1)+P21 -> 9 | S21: =MROUND(O21,1)+Q21 -> 21 | T21: =SUM(S21,R21) -> 30 | U21: Grass | V21: Poison | W21: Dark | X21: Ground | Z21: {=IF(ISBLANK(AK21),_xlfn.LET( _xlpm.nameBeforeSlash, IF(ISNUMBER(SEARCH("/", Y21)), LEFT(Y21, SEARCH("/", Y21)-1), Y21), _xlpm.matchRow, IFERROR(MATCH(_xlpm.nameBeforeSlash, AA:AA, 0), ""), _xlpm.difference, IF(_xlpm.matchRow="", "", ABS((R21 + S21) - (INDEX(R:R, _xlpm.matchRow) + INDEX(S:S, _xlpm.matchRow)))), _xlpm.category, IF(_xlpm.matchRow="", "", INDEX(AJ:AJ, _xlpm.matchRow)), _xlpm.adjustment, IF(_xlpm.matchRow="", "", IF(_xlpm.category="weak", 2, IF(_xlpm.category="moderate", 4, IF(_xlpm.category="strong", 8, IF(_xlpm.category="legendary", _xlpm.difference + 12, IF(_xlpm.category="warp", _xlpm.difference + 12, 0)))))), _xlpm.result, IF(_xlpm.matchRow="", "", IF(_xlpm.category="legendary", _xlpm.adjustment, _xlpm.difference + _xlpm.adjustment)), _xlpm.result ),IF(ISBLANK(Y21),"","Hidden"))} | AA21: Shiny Gigantamax Venusaur | AB21: Gigantamax Form | AC21: G-Max Bloom | AD21: =_xlfn.XLOOKUP(AC21,moves!A:A,moves!B:B) -> grass | AE21: =_xlfn.XLOOKUP(AC21,moves!A:A,moves!D:D) -> 5 | AF21: =_xlfn.XLOOKUP(AC21,moves!A:A,moves!E:E) -> Heal 4. | AG21: 0 | AH21: 0 | AI21: =IF(ISNUMBER(SEARCH("Shiny ", AA21)), 1, 0) -> 1 | AJ21: strong | AL21: 0 | AM21: {=IF(AL21=1,1, IF(ISTEXT(AK21),1, IF(AO21>1,AM20, IF(AI21=1, IF(SUMPRODUCT((LEN($Y$2:$Y$4096)-LEN(SUBSTITUTE($Y$2:$Y$4096,AA21,"")))/LEN(AA21))>0,2,1), IF( SUMPRODUCT((LEN($Y$2:$Y$4096)-LEN(SUBSTITUTE($Y$2:$Y$4096,AA21,"")))/LEN(AA21)) - SUMPRODUCT((LEN($Y$2:$Y$4096)-LEN(SUBSTITUTE($Y$2:$Y$4096,"Alolan "&AA21,"")))/LEN("Alolan "&AA21)) - SUMPRODUCT((LEN($Y$2:$Y$4096)-LEN(SUBSTITUTE($Y$2:$Y$4096,"Galarian "&AA21,"")))/LEN("Galarian "&AA21)) - SUMPRODUCT((LEN($Y$2:$Y$4096)-LEN(SUBSTITUTE($Y$2:$Y$4096,"Hisuian "&AA21,"")))/LEN("Hisuian "&AA21)) - SUMPRODUCT((LEN($Y$2:$Y$4096)-LEN(SUBSTITUTE($Y$2:$Y$4096,"Paldean "&AA21,"")))/LEN("Paldean "&AA21)) >0,2,1) ))))} -> 2 | AN21: 0 | AO21: 3
A22: 4 | B22: Charmander | C22: Fire | E22: 39 | F22: 52 | G22: 43 | H22: 60 | I22: 50 | J22: 65 | K22: Lizard Pokémon | L22: Mountain | M22: Warm | N22: 6.12 | O22: 4.35 | R22: =MROUND(N22,1)+P22 -> 6 | S22: =MROUND(O22,1)+Q22 -> 4 | T22: =SUM(S22,R22) -> 10 | U22: Fire | V22: Flying | W22: Dragon | X22: Ground | Y22: Charmeleon | Z22: {=IF(ISBLANK(AK22),_xlfn.LET( _xlpm.nameBeforeSlash, IF(ISNUMBER(SEARCH("/", Y22)), LEFT(Y22, SEARCH("/", Y22)-1), Y22), _xlpm.matchRow, IFERROR(MATCH(_xlpm.nameBeforeSlash, AA:AA, 0), ""), _xlpm.difference, IF(_xlpm.matchRow="", "", ABS((R22 + S22) - (INDEX(R:R, _xlpm.matchRow) + INDEX(S:S, _xlpm.matchRow)))), _xlpm.category, IF(_xlpm.matchRow="", "", INDEX(AJ:AJ, _xlpm.matchRow)), _xlpm.adjustment, IF(_xlpm.matchRow="", "", IF(_xlpm.category="weak", 2, IF(_xlpm.category="moderate", 4, IF(_xlpm.category="strong", 8, IF(_xlpm.category="legendary", _xlpm.difference + 12, IF(_xlpm.category="warp", _xlpm.difference + 12, 0)))))), _xlpm.result, IF(_xlpm.matchRow="", "", IF(_xlpm.category="legendary", _xlpm.adjustment, _xlpm.difference + _xlpm.adjustment)), _xlpm.result ),IF(ISBLANK(Y22),"","Hidden"))} -> 8 | AA22: Charmander | AC22: Ember | AD22: =_xlfn.XLOOKUP(AC22,moves!A:A,moves!B:B) -> fire | AE22: =_xlfn.XLOOKUP(AC22,moves!A:A,moves!D:D) -> 2 | AF22: =_xlfn.XLOOKUP(AC22,moves!A:A,moves!E:E) -> Inflict the Burned status on the target. | AG22: 1 | AH22: 0 | AI22: =IF(ISNUMBER(SEARCH("Shiny ", AA22)), 1, 0) -> 0 | AJ22: starter | AL22: 0 | AM22: {=IF(AL22=1,1, IF(ISTEXT(AK22),1, IF(AO22>1,AM21, IF(AI22=1, IF(SUMPRODUCT((LEN($Y$2:$Y$4096)-LEN(SUBSTITUTE($Y$2:$Y$4096,AA22,"")))/LEN(AA22))>0,2,1), IF( SUMPRODUCT((LEN($Y$2:$Y$4096)-LEN(SUBSTITUTE($Y$2:$Y$4096,AA22,"")))/LEN(AA22)) - SUMPRODUCT((LEN($Y$2:$Y$4096)-LEN(SUBSTITUTE($Y$2:$Y$4096,"Alolan "&AA22,"")))/LEN("Alolan "&AA22)) - SUMPRODUCT((LEN($Y$2:$Y$4096)-LEN(SUBSTITUTE($Y$2:$Y$4096,"Galarian "&AA22,"")))/LEN("Galarian "&AA22)) - SUMPRODUCT((LEN($Y$2:$Y$4096)-LEN(SUBSTITUTE($Y$2:$Y$4096,"Hisuian "&AA22,"")))/LEN("Hisuian "&AA22)) - SUMPRODUCT((LEN($Y$2:$Y$4096)-LEN(SUBSTITUTE($Y$2:$Y$4096,"Paldean "&AA22,"")))/LEN("Paldean "&AA22)) >0,2,1) ))))} -> 1 | AN22: 0 | AO22: 0
A23: 4-shiny | B23: Charmander | C23: Fire | E23: 39 | F23: 52 | G23: 43 | H23: 60 | I23: 50 | J23: 65 | K23: Lizard Pokémon | L23: Mountain | M23: Warm | N23: 6.12 | O23: 4.35 | R23: =MROUND(N23,1)+P23 -> 6 | S23: =MROUND(O23,1)+Q23 -> 4 | T23: =SUM(S23,R23) -> 10 | U23: Fire | V23: Flying | W23: Dragon | X23: Ground | Y23: Shiny Charmeleon | Z23: {=IF(ISBLANK(AK23),_xlfn.LET( _xlpm.nameBeforeSlash, IF(ISNUMBER(SEARCH("/", Y23)), LEFT(Y23, SEARCH("/", Y23)-1), Y23), _xlpm.matchRow, IFERROR(MATCH(_xlpm.nameBeforeSlash, AA:AA, 0), ""), _xlpm.difference, IF(_xlpm.matchRow="", "", ABS((R23 + S23) - (INDEX(R:R, _xlpm.matchRow) + INDEX(S:S, _xlpm.matchRow)))), _xlpm.category, IF(_xlpm.matchRow="", "", INDEX(AJ:AJ, _xlpm.matchRow)), _xlpm.adjustment, IF(_xlpm.matchRow="", "", IF(_xlpm.category="weak", 2, IF(_xlpm.category="moderate", 4, IF(_xlpm.category="strong", 8, IF(_xlpm.category="legendary", _xlpm.difference + 12, IF(_xlpm.category="warp", _xlpm.difference + 12, 0)))))), _xlpm.result, IF(_xlpm.matchRow="", "", IF(_xlpm.category="legendary", _xlpm.adjustment, _xlpm.difference + _xlpm.adjustment)), _xlpm.result ),IF(ISBLANK(Y23),"","Hidden"))} -> 8 | AA23: Shiny Charmander | AC23: Fire Fang | AD23: =_xlfn.XLOOKUP(AC23,moves!A:A,moves!B:B) -> fire | AE23: =_xlfn.XLOOKUP(AC23,moves!A:A,moves!D:D) -> 3 | AF23: =_xlfn.XLOOKUP(AC23,moves!A:A,moves!E:E) -> If any status symbols are rolled: Inflict the Burned status on the target. | AG23: 1 | AH23: 0 | AI23: =IF(ISNUMBER(SEARCH("Shiny ", AA23)), 1, 0) -> 1 | AJ23: weak | AL23: 0 | AM23: {=IF(AL23=1,1, IF(ISTEXT(AK23),1, IF(AO23>1,AM22, IF(AI23=1, IF(SUMPRODUCT((LEN($Y$2:$Y$4096)-LEN(SUBSTITUTE($Y$2:$Y$4096,AA23,"")))/LEN(AA23))>0,2,1), IF( SUMPRODUCT((LEN($Y$2:$Y$4096)-LEN(SUBSTITUTE($Y$2:$Y$4096,AA23,"")))/LEN(AA23)) - SUMPRODUCT((LEN($Y$2:$Y$4096)-LEN(SUBSTITUTE($Y$2:$Y$4096,"Alolan "&AA23,"")))/LEN("Alolan "&AA23)) - SUMPRODUCT((LEN($Y$2:$Y$4096)-LEN(SUBSTITUTE($Y$2:$Y$4096,"Galarian "&AA23,"")))/LEN("Galarian "&AA23)) - SUMPRODUCT((LEN($Y$2:$Y$4096)-LEN(SUBSTITUTE($Y$2:$Y$4096,"Hisuian "&AA23,"")))/LEN("Hisuian "&AA23)) - SUMPRODUCT((LEN($Y$2:$Y$4096)-LEN(SUBSTITUTE($Y$2:$Y$4096,"Paldean "&AA23,"")))/LEN("Paldean "&AA23)) >0,2,1) ))))} -> 1 | AN23: 0 | AO23: 0
A24: 5 | B24: Charmeleon | C24: Fire | E24: 58 | F24: 64 | G24: 58 | H24: 80 | I24: 65 | J24: 80 | K24: Flame Pokémon | L24: Mountain | M24: Warm | N24: 7.84 | O24: 6.01 | R24: =MROUND(N24,1)+P24 -> 8 | S24: =MROUND(O24,1)+Q24 -> 6 | T24: =SUM(S24,R24) -> 14 | U24: Fire | V24: Flying | W24: Dragon | X24: Ground | Y24: Charizard | Z24: {=IF(ISBLANK(AK24),_xlfn.LET( _xlpm.nameBeforeSlash, IF(ISNUMBER(SEARCH("/", Y24)), LEFT(Y24, SEARCH("/", Y24)-1), Y24), _xlpm.matchRow, IFERROR(MATCH(_xlpm.nameBeforeSlash, AA:AA, 0), ""), _xlpm.difference, IF(_xlpm.matchRow="", "", ABS((R24 + S24) - (INDEX(R:R, _xlpm.matchRow) + INDEX(S:S, _xlpm.matchRow)))), _xlpm.category, IF(_xlpm.matchRow="", "", INDEX(AJ:AJ, _xlpm.matchRow)), _xlpm.adjustment, IF(_xlpm.matchRow="", "", IF(_xlpm.category="weak", 2, IF(_xlpm.category="moderate", 4, IF(_xlpm.category="strong", 8, IF(_xlpm.category="legendary", _xlpm.difference + 12, IF(_xlpm.category="warp", _xlpm.difference + 12, 0)))))), _xlpm.result, IF(_xlpm.matchRow="", "", IF(_xlpm.category="legendary", _xlpm.adjustment, _xlpm.difference + _xlpm.adjustment)), _xlpm.result ),IF(ISBLANK(Y24),"","Hidden"))} -> 14 | AA24: Charmeleon | AC24: Dragon Breath | AD24: =_xlfn.XLOOKUP(AC24,moves!A:A,moves!B:B) -> dragon | AE24: =_xlfn.XLOOKUP(AC24,moves!A:A,moves!D:D) -> 3 | AF24: =_xlfn.XLOOKUP(AC24,moves!A:A,moves!E:E) -> If any status symbols are rolled: Inflict the Paralyzed status on the target. | AG24: 0 | AH24: 0 | AI24: =IF(ISNUMBER(SEARCH("Shiny ", AA24)), 1, 0) -> 0 | AJ24: moderate | AL24: 0 | AM24: {=IF(AL24=1,1, IF(ISTEXT(AK24),1, IF(AO24>1,AM23, IF(AI24=1, IF(SUMPRODUCT((LEN($Y$2:$Y$4096)-LEN(SUBSTITUTE($Y$2:$Y$4096,AA24,"")))/LEN(AA24))>0,2,1), IF( SUMPRODUCT((LEN($Y$2:$Y$4096)-LEN(SUBSTITUTE($Y$2:$Y$4096,AA24,"")))/LEN(AA24)) - SUMPRODUCT((LEN($Y$2:$Y$4096)-LEN(SUBSTITUTE($Y$2:$Y$4096,"Alolan "&AA24,"")))/LEN("Alolan "&AA24)) - SUMPRODUCT((LEN($Y$2:$Y$4096)-LEN(SUBSTITUTE($Y$2:$Y$4096,"Galarian "&AA24,"")))/LEN("Galarian "&AA24)) - SUMPRODUCT((LEN($Y$2:$Y$4096)-LEN(SUBSTITUTE($Y$2:$Y$4096,"Hisuian "&AA24,"")))/LEN("Hisuian "&AA24)) - SUMPRODUCT((LEN($Y$2:$Y$4096)-LEN(SUBSTITUTE($Y$2:$Y$4096,"Paldean "&AA24,"")))/LEN("Paldean "&AA24)) >0,2,1) ))))} -> 2 | AN24: 0 | AO24: 0
A25: 5-shiny | B25: Charmeleon | C25: Fire | E25: 58 | F25: 64 | G25: 58 | H25: 80 | I25: 65 | J25: 80 | K25: Flame Pokémon | L25: Mountain | M25: Warm | N25: 7.84 | O25: 6.01 | R25: =MROUND(N25,1)+P25 -> 8 | S25: =MROUND(O25,1)+Q25 -> 6 | T25: =SUM(S25,R25) -> 14 | U25: Fire | V25: Flying | W25: Dragon | X25: Ground | Y25: Shiny Charizard | Z25: {=IF(ISBLANK(AK25),_xlfn.LET( _xlpm.nameBeforeSlash, IF(ISNUMBER(SEARCH("/", Y25)), LEFT(Y25, SEARCH("/", Y25)-1), Y25), _xlpm.matchRow, IFERROR(MATCH(_xlpm.nameBeforeSlash, AA:AA, 0), ""), _xlpm.difference, IF(_xlpm.matchRow="", "", ABS((R25 + S25) - (INDEX(R:R, _xlpm.matchRow) + INDEX(S:S, _xlpm.matchRow)))), _xlpm.category, IF(_xlpm.matchRow="", "", INDEX(AJ:AJ, _xlpm.matchRow)), _xlpm.adjustment, IF(_xlpm.matchRow="", "", IF(_xlpm.category="weak", 2, IF(_xlpm.category="moderate", 4, IF(_xlpm.category="strong", 8, IF(_xlpm.category="legendary", _xlpm.difference + 12, IF(_xlpm.category="warp", _xlpm.difference + 12, 0)))))), _xlpm.result, IF(_xlpm.matchRow="", "", IF(_xlpm.category="legendary", _xlpm.adjustment, _xlpm.difference + _xlpm.adjustment)), _xlpm.result ),IF(ISBLANK(Y25),"","Hidden"))} -> 14 | AA25: Shiny Charmeleon | AC25: Scorching Sands | AD25: =_xlfn.XLOOKUP(AC25,moves!A:A,moves!B:B) -> ground | AE25: =_xlfn.XLOOKUP(AC25,moves!A:A,moves!D:D) -> 3 | AF25: =_xlfn.XLOOKUP(AC25,moves!A:A,moves!E:E) -> If any status symbols are rolled: Inflict the Burned status on the target | AG25: 0 | AH25: 0 | AI25: =IF(ISNUMBER(SEARCH("Shiny ", AA25)), 1, 0) -> 1 | AJ25: moderate | AL25: 0 | AM25: {=IF(AL25=1,1, IF(ISTEXT(AK25),1, IF(AO25>1,AM24, IF(AI25=1, IF(SUMPRODUCT((LEN($Y$2:$Y$4096)-LEN(SUBSTITUTE($Y$2:$Y$4096,AA25,"")))/LEN(AA25))>0,2,1), IF( SUMPRODUCT((LEN($Y$2:$Y$4096)-LEN(SUBSTITUTE($Y$2:$Y$4096,AA25,"")))/LEN(AA25)) - SUMPRODUCT((LEN($Y$2:$Y$4096)-LEN(SUBSTITUTE($Y$2:$Y$4096,"Alolan "&AA25,"")))/LEN("Alolan "&AA25)) - SUMPRODUCT((LEN($Y$2:$Y$4096)-LEN(SUBSTITUTE($Y$2:$Y$4096,"Galarian "&AA25,"")))/LEN("Galarian "&AA25)) - SUMPRODUCT((LEN($Y$2:$Y$4096)-LEN(SUBSTITUTE($Y$2:$Y$4096,"Hisuian "&AA25,"")))/LEN("Hisuian "&AA25)) - SUMPRODUCT((LEN($Y$2:$Y$4096)-LEN(SUBSTITUTE($Y$2:$Y$4096,"Paldean "&AA25,"")))/LEN("Paldean "&AA25)) >0,2,1) ))))} -> 2 | AN25: 0 | AO25: 0
A26: 6 | B26: Charizard | C26: Fire | D26: Flying | E26: 78 | F26: 84 | G26: 78 | H26: 109 | I26: 85 | J26: 100 | K26: Flame Pokémon | L26: Mountain | M26: Warm | N26: 10.29 | O26: 8.01 | P26: 1 | Q26: 1 | R26: =MROUND(N26,1)+P26 -> 11 | S26: =MROUND(O26,1)+Q26 -> 9 | T26: =SUM(S26,R26) -> 20 | U26: Fire | V26: Flying | W26: Dragon | X26: Ground | Z26: {=IF(ISBLANK(AK26),_xlfn.LET( _xlpm.nameBeforeSlash, IF(ISNUMBER(SEARCH("/", Y26)), LEFT(Y26, SEARCH("/", Y26)-1), Y26), _xlpm.matchRow, IFERROR(MATCH(_xlpm.nameBeforeSlash, AA:AA, 0), ""), _xlpm.difference, IF(_xlpm.matchRow="", "", ABS((R26 + S26) - (INDEX(R:R, _xlpm.matchRow) + INDEX(S:S, _xlpm.matchRow)))), _xlpm.category, IF(_xlpm.matchRow="", "", INDEX(AJ:AJ, _xlpm.matchRow)), _xlpm.adjustment, IF(_xlpm.matchRow="", "", IF(_xlpm.category="weak", 2, IF(_xlpm.category="moderate", 4, IF(_xlpm.category="strong", 8, IF(_xlpm.category="legendary", _xlpm.difference + 12, IF(_xlpm.category="warp", _xlpm.difference + 12, 0)))))), _xlpm.result, IF(_xlpm.matchRow="", "", IF(_xlpm.category="legendary", _xlpm.adjustment, _xlpm.difference + _xlpm.adjustment)), _xlpm.result ),IF(ISBLANK(Y26),"","Hidden"))} | AA26: Charizard | AC26: Flamethrower | AD26: =_xlfn.XLOOKUP(AC26,moves!A:A,moves!B:B) -> fire | AE26: =_xlfn.XLOOKUP(AC26,moves!A:A,moves!D:D) -> 4 | AF26: =_xlfn.XLOOKUP(AC26,moves!A:A,moves!E:E) -> If any status symbols are rolled: Inflict the Burned status on the target. | AG26: 0 | AH26: 0 | AI26: =IF(ISNUMBER(SEARCH("Shiny ", AA26)), 1, 0) -> 0 | AJ26: strong | AL26: 0 | AM26: {=IF(AL26=1,1, IF(ISTEXT(AK26),1, IF(AO26>1,AM25, IF(AI26=1, IF(SUMPRODUCT((LEN($Y$2:$Y$4096)-LEN(SUBSTITUTE($Y$2:$Y$4096,AA26,"")))/LEN(AA26))>0,2,1), IF( SUMPRODUCT((LEN($Y$2:$Y$4096)-LEN(SUBSTITUTE($Y$2:$Y$4096,AA26,"")))/LEN(AA26)) - SUMPRODUCT((LEN($Y$2:$Y$4096)-LEN(SUBSTITUTE($Y$2:$Y$4096,"Alolan "&AA26,"")))/LEN("Alolan "&AA26)) - SUMPRODUCT((LEN($Y$2:$Y$4096)-LEN(SUBSTITUTE($Y$2:$Y$4096,"Galarian "&AA26,"")))/LEN("Galarian "&AA26)) - SUMPRODUCT((LEN($Y$2:$Y$4096)-LEN(SUBSTITUTE($Y$2:$Y$4096,"Hisuian "&AA26,"")))/LEN("Hisuian "&AA26)) - SUMPRODUCT((LEN($Y$2:$Y$4096)-LEN(SUBSTITUTE($Y$2:$Y$4096,"Paldean "&AA26,"")))/LEN("Paldean "&AA26)) >0,2,1) ))))} -> 2 | AN26: 0 | AO26: 1
A27: 6-mx | B27: Charizard | C27: Fire | D27: Dragon | E27: 78 | F27: 130 | G27: 111 | H27: 130 | I27: 85 | J27: 100 | K27: Flame Pokémon | L27: blank | M27: Mega | N27: 11.8 | O27: 9 | P27: 1 | Q27: 2 | R27: =MROUND(N27,1)+P27 -> 13 | S27: =MROUND(O27,1)+Q27 -> 11 | T27: =SUM(S27,R27) -> 24 | U27: Fire | V27: Dragon | W27: Flying | X27: Ground | Z27: {=IF(ISBLANK(AK27),_xlfn.LET( _xlpm.nameBeforeSlash, IF(ISNUMBER(SEARCH("/", Y27)), LEFT(Y27, SEARCH("/", Y27)-1), Y27), _xlpm.matchRow, IFERROR(MATCH(_xlpm.nameBeforeSlash, AA:AA, 0), ""), _xlpm.difference, IF(_xlpm.matchRow="", "", ABS((R27 + S27) - (INDEX(R:R, _xlpm.matchRow) + INDEX(S:S, _xlpm.matchRow)))), _xlpm.category, IF(_xlpm.matchRow="", "", INDEX(AJ:AJ, _xlpm.matchRow)), _xlpm.adjustment, IF(_xlpm.matchRow="", "", IF(_xlpm.category="weak", 2, IF(_xlpm.category="moderate", 4, IF(_xlpm.category="strong", 8, IF(_xlpm.category="legendary", _xlpm.difference + 12, IF(_xlpm.category="warp", _xlpm.difference + 12, 0)))))), _xlpm.result, IF(_xlpm.matchRow="", "", IF(_xlpm.category="legendary", _xlpm.adjustment, _xlpm.difference + _xlpm.adjustment)), _xlpm.result ),IF(ISBLANK(Y27),"","Hidden"))} | AA27: Mega Charizard X | AB27: Mega Form X | AC27: Blast Burn | AD27: =_xlfn.XLOOKUP(AC27,moves!A:A,moves!B:B) -> fire | AE27: =_xlfn.XLOOKUP(AC27,moves!A:A,moves!D:D) -> 8 | AF27: =_xlfn.XLOOKUP(AC27,moves!A:A,moves!E:E) | AG27: 0 | AH27: 0 | AI27: =IF(ISNUMBER(SEARCH("Shiny ", AA27)), 1, 0) -> 0 | AJ27: strong | AL27: 0 | AM27: {=IF(AL27=1,1, IF(ISTEXT(AK27),1, IF(AO27>1,AM26, IF(AI27=1, IF(SUMPRODUCT((LEN($Y$2:$Y$4096)-LEN(SUBSTITUTE($Y$2:$Y$4096,AA27,"")))/LEN(AA27))>0,2,1), IF( SUMPRODUCT((LEN($Y$2:$Y$4096)-LEN(SUBSTITUTE($Y$2:$Y$4096,AA27,"")))/LEN(AA27)) - SUMPRODUCT((LEN($Y$2:$Y$4096)-LEN(SUBSTITUTE($Y$2:$Y$4096,"Alolan "&AA27,"")))/LEN("Alolan "&AA27)) - SUMPRODUCT((LEN($Y$2:$Y$4096)-LEN(SUBSTITUTE($Y$2:$Y$4096,"Galarian "&AA27,"")))/LEN("Galarian "&AA27)) - SUMPRODUCT((LEN($Y$2:$Y$4096)-LEN(SUBSTITUTE($Y$2:$Y$4096,"Hisuian "&AA27,"")))/LEN("Hisuian "&AA27)) - SUMPRODUCT((LEN($Y$2:$Y$4096)-LEN(SUBSTITUTE($Y$2:$Y$4096,"Paldean "&AA27,"")))/LEN("Paldean "&AA27)) >0,2,1) ))))} -> 2 | AN27: 0 | AO27: 2
